Workbook

Sheet Home
D7: (nazwa spółki oraz NIP)
D13: (data dostawy)
D17: (tutaj zacznij pisać)

Sheet koniec serii
J6: Dane logistyczne | N6: Ilość zamawianych
N7: opakowań
O8: 0 | S8: DMC0001
I9: =INDEX(Wsad_Ofertowy[#Data],MATCH(S8,Wsad_Ofertowy[Kod],0),21) -> 10 | J9: sztuk w opakowaniu
J10: KONIEC SERII
D11: =INDEX(Wsad_Ofertowy[#Data],MATCH(S8,Wsad_Ofertowy[Kod],0),4) -> Z 399 aniołek | G11: {=INDEX(Wsad_Ofertowy[#Data],MATCH(S8,Wsad_Ofertowy[Kod],0),'Generowanie podsumowania zam'!$U$1)} -> 2.99 | R11: =I9*G11*O8 -> 0
E12: =INDEX(Wsad_Ofertowy[#Data],MATCH(S8,Wsad_Ofertowy[Kod],0),5) -> 5907702531991 | G12: cena za szt. | R12: wartość zamawiana
J17: Dane logistyczne | N17: Ilość zamawianych
N18: opakowań
O19: 0 | S19: CZNI0607
I20: =INDEX(Wsad_Ofertowy[#Data],MATCH(S19,Wsad_Ofertowy[Kod],0),21) -> 9 | J20: sztuk w opakowaniu
J21: KONIEC SERII
D22: =INDEX(Wsad_Ofertowy[#Data],MATCH(S19,Wsad_Ofertowy[Kod],0),4) -> Z 470 zalewany | G22: {=INDEX(Wsad_Ofertowy[#Data],MATCH(S19,Wsad_Ofertowy[Kod],0),'Generowanie podsumowania zam'!$U$1)} -> 4.39 | R22: =I20*G22*O19 -> 0
E23: =INDEX(Wsad_Ofertowy[#Data],MATCH(S19,Wsad_Ofertowy[Kod],0),5) -> 5907702531038 | G23: cena za szt. | R23: wartość zamawiana
J28: Dane logistyczne | N28: Ilość zamawianych
N29: opakowań
O30: 0 | S30: ZAJA0352
I31: =INDEX(Wsad_Ofertowy[#Data],MATCH(S30,Wsad_Ofertowy[Kod],0),21) -> 8 | J31: sztuk w opakowaniu
J32: KONIEC SERII
D33: =INDEX(Wsad_Ofertowy[#Data],MATCH(S30,Wsad_Ofertowy[Kod],0),4) -> Z 467 ZŁ | G33: {=INDEX(Wsad_Ofertowy[#Data],MATCH(S30,Wsad_Ofertowy[Kod],0),'Generowanie podsumowania zam'!$U$1)} -> 6.52 | R33: =I31*G33*O30 -> 0
E34: =INDEX(Wsad_Ofertowy[#Data],MATCH(S30,Wsad_Ofertowy[Kod],0),5) -> 5907702525242 | G34: cena za szt. | R34: wartość zamawiana
J39: Dane logistyczne | N39: Ilość zamawianych
N40: opakowań
O41: 0 | S41: ZAJA0463
I42: =INDEX(Wsad_Ofertowy[#Data],MATCH(S41,Wsad_Ofertowy[Kod],0),21) -> 8 | J42: sztuk w opakowaniu
J43: KONIEC SERII
D44: =INDEX(Wsad_Ofertowy[#Data],MATCH(S41,Wsad_Ofertowy[Kod],0),4) -> Z 467 sr | G44: {=INDEX(Wsad_Ofertowy[#Data],MATCH(S41,Wsad_Ofertowy[Kod],0),'Generowanie podsumowania zam'!$U$1)} -> 6.52 | R44: =I42*G44*O41 -> 0
E45: =INDEX(Wsad_Ofertowy[#Data],MATCH(S41,Wsad_Ofertowy[Kod],0),5) -> 5907702525242 | G45: cena za szt. | R45: wartość zamawiana
J50: Dane logistyczne | N50: Ilość zamawianych
N51: opakowań
O52: 0 | S52: ZAJA0440
I53: =INDEX(Wsad_Ofertowy[#Data],MATCH(S52,Wsad_Ofertowy[Kod],0),21) -> 5 | J53: sztuk w opakowaniu
J54: KONIEC SERII
D55: =INDEX(Wsad_Ofertowy[#Data],MATCH(S52,Wsad_Ofertowy[Kod],0),4) -> Kulka B. SR | G55: {=INDEX(Wsad_Ofertowy[#Data],MATCH(S52,Wsad_Ofertowy[Kod],0),'Generowanie podsumowania zam'!$U$1)} -> 5.99 | R55: =I53*G55*O52 -> 0
E56: =INDEX(Wsad_Ofertowy[#Data],MATCH(S52,Wsad_Ofertowy[Kod],0),5) -> 5907702534619 | G56: cena za szt. | R56: wartość zamawiana
J61: Dane logistyczne | N61: Ilość zamawianych
N62: opakowań
O63: 0 | S63: ZAJA0441
I64: =INDEX(Wsad_Ofertowy[#Data],MATCH(S63,Wsad_Ofertowy[Kod],0),21) -> 5 | J64: sztuk w opakowaniu
J65: KONIEC SERII
...

Sheet małe
J6: Dane logistyczne | N6: Ilość zamawianych
N7: opakowań
O8: 0 | S8: CZNI1268
I9: =INDEX(Wsad_Ofertowy[#Data],MATCH(S8,Wsad_Ofertowy[Kod],0),21) -> 8 | J9: sztuk w opakowaniu
D11: =INDEX(Wsad_Ofertowy[#Data],MATCH(S8,Wsad_Ofertowy[Kod],0),4) -> Znicz szklany Z 02 ZŁ-P. | G11: {=INDEX(Wsad_Ofertowy[#Data],MATCH(S8,Wsad_Ofertowy[Kod],0),'Generowanie podsumowania zam'!$U$1)} -> 3.99 | R11: =I9*G11*O8 -> 0
E12: =INDEX(Wsad_Ofertowy[#Data],MATCH(S8,Wsad_Ofertowy[Kod],0),5) -> 5907702533803 | G12: cena za szt. | R12: wartość zamawiana
J17: Dane logistyczne | N17: Ilość zamawianych
N18: opakowań
O19: 0 | S19: CZNI1266
I20: =INDEX(Wsad_Ofertowy[#Data],MATCH(S19,Wsad_Ofertowy[Kod],0),21) -> 8 | J20: sztuk w opakowaniu
D22: =INDEX(Wsad_Ofertowy[#Data],MATCH(S19,Wsad_Ofertowy[Kod],0),4) -> Z 02 Krzyż SR-P. | G22: {=INDEX(Wsad_Ofertowy[#Data],MATCH(S19,Wsad_Ofertowy[Kod],0),'Generowanie podsumowania zam'!$U$1)} -> 4.25 | R22: =I20*G22*O19 -> 0
E23: =INDEX(Wsad_Ofertowy[#Data],MATCH(S19,Wsad_Ofertowy[Kod],0),5) -> 5907702533780 | G23: cena za szt. | R23: wartość zamawiana
J28: Dane logistyczne | N28: Ilość zamawianych
N29: opakowań
O30: 0 | S30: CZNI1343
I31: =INDEX(Wsad_Ofertowy[#Data],MATCH(S30,Wsad_Ofertowy[Kod],0),21) -> 8 | J31: sztuk w opakowaniu
D33: =INDEX(Wsad_Ofertowy[#Data],MATCH(S30,Wsad_Ofertowy[Kod],0),4) -> Z 02 wianek | G33: {=INDEX(Wsad_Ofertowy[#Data],MATCH(S30,Wsad_Ofertowy[Kod],0),'Generowanie podsumowania zam'!$U$1)} -> 4.48 | R33: =I31*G33*O30 -> 0
E34: =INDEX(Wsad_Ofertowy[#Data],MATCH(S30,Wsad_Ofertowy[Kod],0),5) -> 5907702537795 | G34: cena za szt. | R34: wartość zamawiana
J39: Dane logistyczne | N39: Ilość zamawianych
N40: opakowań
O41: 0 | S41: CZNI0469
I42: =INDEX(Wsad_Ofertowy[#Data],MATCH(S41,Wsad_Ofertowy[Kod],0),21) -> 9 | J42: sztuk w opakowaniu
D44: =INDEX(Wsad_Ofertowy[#Data],MATCH(S41,Wsad_Ofertowy[Kod],0),4) -> Z 273 cukier zł | G44: {=INDEX(Wsad_Ofertowy[#Data],MATCH(S41,Wsad_Ofertowy[Kod],0),'Generowanie podsumowania zam'!$U$1)} -> 6.39 | R44: =I42*G44*O41 -> 0
E45: =INDEX(Wsad_Ofertowy[#Data],MATCH(S41,Wsad_Ofertowy[Kod],0),5) -> 5907702505848 | G45: cena za szt. | R45: wartość zamawiana
J50: Dane logistyczne | N50: Ilość zamawianych
N51: opakowań
O52: 0 | S52: ZAJA0443
I53: =INDEX(Wsad_Ofertowy[#Data],MATCH(S52,Wsad_Ofertowy[Kod],0),21) -> 8 | J53: sztuk w opakowaniu
D55: =INDEX(Wsad_Ofertowy[#Data],MATCH(S52,Wsad_Ofertowy[Kod],0),4) -> Z 569 Krzyż ZŁ | G55: {=INDEX(Wsad_Ofertowy[#Data],MATCH(S52,Wsad_Ofertowy[Kod],0),'Generowanie podsumowania zam'!$U$1)} -> 5.99 | R55: =I53*G55*O52 -> 0
E56: =INDEX(Wsad_Ofertowy[#Data],MATCH(S52,Wsad_Ofertowy[Kod],0),5) -> 5907702534817 | G56: cena za szt. | R56: wartość zamawiana
J61: Dane logistyczne | N61: Ilość zamawianych
N62: opakowań
O63: 0 | S63: ZAJA0442
I64: =INDEX(Wsad_Ofertowy[#Data],MATCH(S63,Wsad_Ofertowy[Kod],0),21) -> 8 | J64: sztuk w opakowaniu
D66: =INDEX(Wsad_Ofertowy[#Data],MATCH(S63,Wsad_Ofertowy[Kod],0),4) -> Z 569 Krzyż SR | G66: {=INDEX(Wsad_Ofertowy[#Data],MATCH(S63,Wsad_Ofertowy[Kod],0),'Generowanie podsumowania zam'!$U$1)} -> 5.99 | R66: =I64*G66*O63 -> 0
E67: =INDEX(Wsad_Ofertowy[#Data],MATCH(S63,Wsad_Ofertowy[Kod],0),5) -> 5907702534800 | G67: cena za szt. | R67: wartość zamawiana
J72: Dane logistyczne | N72: Ilość zamawianych
N73: opakowań
O74: 0 | S74: CZNI1273
I75: =INDEX(Wsad_Ofertowy[#Data],MATCH(S74,Wsad_Ofertowy[Kod],0),21) -> 8 | J75: sztuk w opakowaniu
...

Sheet średnie
J6: Dane logistyczne | N6: Ilość zamawianych
N7: opakowań
O8: 0 | S8: CZNI1274
I9: =INDEX(Wsad_Ofertowy[#Data],MATCH(S8,Wsad_Ofertowy[Kod],0),21) -> 7 | J9: sztuk w opakowaniu
D11: =INDEX(Wsad_Ofertowy[#Data],MATCH(S8,Wsad_Ofertowy[Kod],0),4) -> Kwadrat AT lilie SR-P. | G11: {=INDEX(Wsad_Ofertowy[#Data],MATCH(S8,Wsad_Ofertowy[Kod],0),'Generowanie podsumowania zam'!$U$1)} -> 8.79 | R11: =I9*G11*O8 -> 0
E12: =INDEX(Wsad_Ofertowy[#Data],MATCH(S8,Wsad_Ofertowy[Kod],0),5) -> 5907702533872 | G12: cena za szt. | R12: wartość zamawiana
J17: Dane logistyczne | N17: Ilość zamawianych
N18: opakowań
O19: 0 | S19: CZNI1277
I20: =INDEX(Wsad_Ofertowy[#Data],MATCH(S19,Wsad_Ofertowy[Kod],0),21) -> 7 | J20: sztuk w opakowaniu
D22: =INDEX(Wsad_Ofertowy[#Data],MATCH(S19,Wsad_Ofertowy[Kod],0),4) -> Kwadrat AT lilie ZŁ-P. | G22: {=INDEX(Wsad_Ofertowy[#Data],MATCH(S19,Wsad_Ofertowy[Kod],0),'Generowanie podsumowania zam'!$U$1)} -> 8.79 | R22: =I20*G22*O19 -> 0
E23: =INDEX(Wsad_Ofertowy[#Data],MATCH(S19,Wsad_Ofertowy[Kod],0),5) -> 5907702533889 | G23: cena za szt. | R23: wartość zamawiana
J28: Dane logistyczne | N28: Ilość zamawianych
N29: opakowań
O30: 0 | S30: CZNI1337
I31: =INDEX(Wsad_Ofertowy[#Data],MATCH(S30,Wsad_Ofertowy[Kod],0),21) -> 6 | J31: sztuk w opakowaniu
D33: =INDEX(Wsad_Ofertowy[#Data],MATCH(S30,Wsad_Ofertowy[Kod],0),4) -> L 1435 aplikacja SR | G33: {=INDEX(Wsad_Ofertowy[#Data],MATCH(S30,Wsad_Ofertowy[Kod],0),'Generowanie podsumowania zam'!$U$1)} -> 9.55 | R33: =I31*G33*O30 -> 0
E34: =INDEX(Wsad_Ofertowy[#Data],MATCH(S30,Wsad_Ofertowy[Kod],0),5) -> 5907702537740 | G34: cena za szt. | R34: wartość zamawiana
J39: Dane logistyczne | N39: Ilość zamawianych
N40: opakowań
O41: 0 | S41: CZNI1338
I42: =INDEX(Wsad_Ofertowy[#Data],MATCH(S41,Wsad_Ofertowy[Kod],0),21) -> 6 | J42: sztuk w opakowaniu
D44: =INDEX(Wsad_Ofertowy[#Data],MATCH(S41,Wsad_Ofertowy[Kod],0),4) -> L 1435 aplikacja ZŁ | G44: {=INDEX(Wsad_Ofertowy[#Data],MATCH(S41,Wsad_Ofertowy[Kod],0),'Generowanie podsumowania zam'!$U$1)} -> 9.55 | R44: =I42*G44*O41 -> 0
E45: =INDEX(Wsad_Ofertowy[#Data],MATCH(S41,Wsad_Ofertowy[Kod],0),5) -> 5907702537757 | G45: cena za szt. | R45: wartość zamawiana
J50: Dane logistyczne | N50: Ilość zamawianych
N51: opakowań
O52: 0 | S52: DAVP0036
I53: =INDEX(Wsad_Ofertowy[#Data],MATCH(S52,Wsad_Ofertowy[Kod],0),21) -> 6 | J53: sztuk w opakowaniu
D55: =INDEX(Wsad_Ofertowy[#Data],MATCH(S52,Wsad_Ofertowy[Kod],0),4) -> Owal sentencja SR | G55: {=INDEX(Wsad_Ofertowy[#Data],MATCH(S52,Wsad_Ofertowy[Kod],0),'Generowanie podsumowania zam'!$U$1)} -> 8.99 | R55: =I53*G55*O52 -> 0
E56: =INDEX(Wsad_Ofertowy[#Data],MATCH(S52,Wsad_Ofertowy[Kod],0),5) -> 5907702536040 | G56: cena za szt. | R56: wartość zamawiana
J61: Dane logistyczne | N61: Ilość zamawianych
N62: opakowań
O63: 0 | S63: DAVP0035
I64: =INDEX(Wsad_Ofertowy[#Data],MATCH(S63,Wsad_Ofertowy[Kod],0),21) -> 6 | J64: sztuk w opakowaniu
D66: =INDEX(Wsad_Ofertowy[#Data],MATCH(S63,Wsad_Ofertowy[Kod],0),4) -> Owal sentencja ZŁ | G66: {=INDEX(Wsad_Ofertowy[#Data],MATCH(S63,Wsad_Ofertowy[Kod],0),'Generowanie podsumowania zam'!$U$1)} -> 8.99 | R66: =I64*G66*O63 -> 0
E67: =INDEX(Wsad_Ofertowy[#Data],MATCH(S63,Wsad_Ofertowy[Kod],0),5) -> 5907702536057 | G67: cena za szt. | R67: wartość zamawiana
J72: Dane logistyczne | N72: Ilość zamawianych
N73: opakowań
O74: 0 | S74: CZNI1280
I75: =INDEX(Wsad_Ofertowy[#Data],MATCH(S74,Wsad_Ofertowy[Kod],0),21) -> 6 | J75: sztuk w opakowaniu
...

Sheet duże
J6: Dane logistyczne | N6: Ilość zamawianych
N7: opakowań
O8: 0 | S8: CZNI1265
I9: =INDEX(Wsad_Ofertowy[#Data],MATCH(S8,Wsad_Ofertowy[Kod],0),21) -> 4 | J9: sztuk w opakowaniu
D11: =INDEX(Wsad_Ofertowy[#Data],MATCH(S8,Wsad_Ofertowy[Kod],0),4) -> Diament D 9 tęcza SR-P. | G11: {=INDEX(Wsad_Ofertowy[#Data],MATCH(S8,Wsad_Ofertowy[Kod],0),'Generowanie podsumowania zam'!$U$1)} -> 15.05 | R11: =I9*G11*O8 -> 0
E12: =INDEX(Wsad_Ofertowy[#Data],MATCH(S8,Wsad_Ofertowy[Kod],0),5) -> 5907702533773 | G12: cena za szt. | R12: wartość zamawiana
J17: Dane logistyczne | N17: Ilość zamawianych
N18: opakowań
O19: 0 | S19: CZNI1264
I20: =INDEX(Wsad_Ofertowy[#Data],MATCH(S19,Wsad_Ofertowy[Kod],0),21) -> 4 | J20: sztuk w opakowaniu
D22: =INDEX(Wsad_Ofertowy[#Data],MATCH(S19,Wsad_Ofertowy[Kod],0),4) -> Diament D 9 tęcza ZŁ-P. | G22: {=INDEX(Wsad_Ofertowy[#Data],MATCH(S19,Wsad_Ofertowy[Kod],0),'Generowanie podsumowania zam'!$U$1)} -> 15.05 | R22: =I20*G22*O19 -> 0
E23: =INDEX(Wsad_Ofertowy[#Data],MATCH(S19,Wsad_Ofertowy[Kod],0),5) -> 5907702533759 | G23: cena za szt. | R23: wartość zamawiana
J28: Dane logistyczne | N28: Ilość zamawianych
N29: opakowań
O30: 0 | S30: CZNI1260
I31: =INDEX(Wsad_Ofertowy[#Data],MATCH(S30,Wsad_Ofertowy[Kod],0),21) -> 4 | J31: sztuk w opakowaniu
D33: =INDEX(Wsad_Ofertowy[#Data],MATCH(S30,Wsad_Ofertowy[Kod],0),4) -> Koniak K 9 SR-P. | G33: {=INDEX(Wsad_Ofertowy[#Data],MATCH(S30,Wsad_Ofertowy[Kod],0),'Generowanie podsumowania zam'!$U$1)} -> 15.05 | R33: =I31*G33*O30 -> 0
E34: =INDEX(Wsad_Ofertowy[#Data],MATCH(S30,Wsad_Ofertowy[Kod],0),5) -> 5907702534039 | G34: cena za szt. | R34: wartość zamawiana
J39: Dane logistyczne | N39: Ilość zamawianych
N40: opakowań
O41: 0 | S41: ZAJA0422
I42: =INDEX(Wsad_Ofertowy[#Data],MATCH(S41,Wsad_Ofertowy[Kod],0),21) -> 4 | J42: sztuk w opakowaniu
D44: =INDEX(Wsad_Ofertowy[#Data],MATCH(S41,Wsad_Ofertowy[Kod],0),4) -> Koniak Kryształ SR | G44: {=INDEX(Wsad_Ofertowy[#Data],MATCH(S41,Wsad_Ofertowy[Kod],0),'Generowanie podsumowania zam'!$U$1)} -> 17.49 | R44: =I42*G44*O41 -> 0
E45: =INDEX(Wsad_Ofertowy[#Data],MATCH(S41,Wsad_Ofertowy[Kod],0),5) -> 5907702534633 | G45: cena za szt. | R45: wartość zamawiana
J50: Dane logistyczne | N50: Ilość zamawianych
N51: opakowań
O52: 0 | S52: CZNI1169
I53: =INDEX(Wsad_Ofertowy[#Data],MATCH(S52,Wsad_Ofertowy[Kod],0),21) -> 4 | J53: sztuk w opakowaniu
D55: =INDEX(Wsad_Ofertowy[#Data],MATCH(S52,Wsad_Ofertowy[Kod],0),4) -> KWK 19 drzewo SR | G55: {=INDEX(Wsad_Ofertowy[#Data],MATCH(S52,Wsad_Ofertowy[Kod],0),'Generowanie podsumowania zam'!$U$1)} -> 18.49 | R55: =I53*G55*O52 -> 0
E56: =INDEX(Wsad_Ofertowy[#Data],MATCH(S52,Wsad_Ofertowy[Kod],0),5) -> 5907702536699 | G56: cena za szt. | R56: wartość zamawiana
J61: Dane logistyczne | N61: Ilość zamawianych
N62: opakowań
O63: 0 | S63: CZNI1170
I64: =INDEX(Wsad_Ofertowy[#Data],MATCH(S63,Wsad_Ofertowy[Kod],0),21) -> 4 | J64: sztuk w opakowaniu
D66: =INDEX(Wsad_Ofertowy[#Data],MATCH(S63,Wsad_Ofertowy[Kod],0),4) -> KWK 19 drzewo ZŁ | G66: {=INDEX(Wsad_Ofertowy[#Data],MATCH(S63,Wsad_Ofertowy[Kod],0),'Generowanie podsumowania zam'!$U$1)} -> 18.49 | R66: =I64*G66*O63 -> 0
E67: =INDEX(Wsad_Ofertowy[#Data],MATCH(S63,Wsad_Ofertowy[Kod],0),5) -> 5907702536705 | G67: cena za szt. | R67: wartość zamawiana
J72: Dane logistyczne | N72: Ilość zamawianych
N73: opakowań
O74: 0 | S74: CZNI40214
I75: =INDEX(Wsad_Ofertowy[#Data],MATCH(S74,Wsad_Ofertowy[Kod],0),21) -> 4 | J75: sztuk w opakowaniu
...

Sheet zalewane
J6: Dane logistyczne | N6: Ilość zamawianych
N7: opakowań
O8: 0 | S8: CZNI1013
I9: =INDEX(Wsad_Ofertowy[#Data],MATCH(S8,Wsad_Ofertowy[Kod],0),21) -> 1 | J9: sztuk w opakowaniu
D11: =INDEX(Wsad_Ofertowy[#Data],MATCH(S8,Wsad_Ofertowy[Kod],0),4) -> Znicz otwarty Misa duża nakrapiana Czarna | G11: {=INDEX(Wsad_Ofertowy[#Data],MATCH(S8,Wsad_Ofertowy[Kod],0),'Generowanie podsumowania zam'!$U$1)} -> 70.26 | R11: =I9*G11*O8 -> 0
E12: =INDEX(Wsad_Ofertowy[#Data],MATCH(S8,Wsad_Ofertowy[Kod],0),5) -> 5907702535548 | G12: cena za szt. | R12: wartość zamawiana
J17: Dane logistyczne | N17: Ilość zamawianych
N18: opakowań
O19: 0 | S19: CZNI1025
I20: =INDEX(Wsad_Ofertowy[#Data],MATCH(S19,Wsad_Ofertowy[Kod],0),21) -> 1 | J20: sztuk w opakowaniu
D22: =INDEX(Wsad_Ofertowy[#Data],MATCH(S19,Wsad_Ofertowy[Kod],0),4) -> Znicz otwarty Misa mała nakrapiana Czarna | G22: {=INDEX(Wsad_Ofertowy[#Data],MATCH(S19,Wsad_Ofertowy[Kod],0),'Generowanie podsumowania zam'!$U$1)} -> 47.2 | R22: =I20*G22*O19 -> 0
E23: =INDEX(Wsad_Ofertowy[#Data],MATCH(S19,Wsad_Ofertowy[Kod],0),5) -> 5907702535555 | G23: cena za szt. | R23: wartość zamawiana

Sheet okazjonalne
J6: Dane logistyczne | N6: Ilość zamawianych
N7: opakowań
O8: 0 | S8: DAVP0066
I9: =INDEX(Wsad_Ofertowy[#Data],MATCH(S8,Wsad_Ofertowy[Kod],0),21) -> 7 | J9: sztuk w opakowaniu
D11: =INDEX(Wsad_Ofertowy[#Data],MATCH(S8,Wsad_Ofertowy[Kod],0),4) -> L 1210 Serce Tata Białe | G11: {=INDEX(Wsad_Ofertowy[#Data],MATCH(S8,Wsad_Ofertowy[Kod],0),'Generowanie podsumowania zam'!$U$1)} -> 8.19 | R11: =I9*G11*O8 -> 0
E12: =INDEX(Wsad_Ofertowy[#Data],MATCH(S8,Wsad_Ofertowy[Kod],0),5) -> 5907702534091 | G12: cena za szt. | R12: wartość zamawiana
J17: Dane logistyczne | N17: Ilość zamawianych
N18: opakowań
O19: 0 | S19: CZNI0944
I20: =INDEX(Wsad_Ofertowy[#Data],MATCH(S19,Wsad_Ofertowy[Kod],0),21) -> 6 | J20: sztuk w opakowaniu
D22: =INDEX(Wsad_Ofertowy[#Data],MATCH(S19,Wsad_Ofertowy[Kod],0),4) -> L 1750 kochanym rodzicom sr | G22: {=INDEX(Wsad_Ofertowy[#Data],MATCH(S19,Wsad_Ofertowy[Kod],0),'Generowanie podsumowania zam'!$U$1)} -> 11.35 | R22: =I20*G22*O19 -> 0
E23: =INDEX(Wsad_Ofertowy[#Data],MATCH(S19,Wsad_Ofertowy[Kod],0),5) -> 5907702532974 | G23: cena za szt. | R23: wartość zamawiana
J28: Dane logistyczne | N28: Ilość zamawianych
N29: opakowań
O30: 0 | S30: CZNI0945
I31: =INDEX(Wsad_Ofertowy[#Data],MATCH(S30,Wsad_Ofertowy[Kod],0),21) -> 6 | J31: sztuk w opakowaniu
D33: =INDEX(Wsad_Ofertowy[#Data],MATCH(S30,Wsad_Ofertowy[Kod],0),4) -> L 1750 kochanym rodzicom zł | G33: {=INDEX(Wsad_Ofertowy[#Data],MATCH(S30,Wsad_Ofertowy[Kod],0),'Generowanie podsumowania zam'!$U$1)} -> 11.35 | R33: =I31*G33*O30 -> 0
E34: =INDEX(Wsad_Ofertowy[#Data],MATCH(S30,Wsad_Ofertowy[Kod],0),5) -> 5907702532967 | G34: cena za szt. | R34: wartość zamawiana
J39: Dane logistyczne | N39: Ilość zamawianych
N40: opakowań
O41: 0 | S41: CZNI0701
I42: =INDEX(Wsad_Ofertowy[#Data],MATCH(S41,Wsad_Ofertowy[Kod],0),21) -> 4 | J42: sztuk w opakowaniu
D44: =INDEX(Wsad_Ofertowy[#Data],MATCH(S41,Wsad_Ofertowy[Kod],0),4) -> L 2710 mama/sr | G44: {=INDEX(Wsad_Ofertowy[#Data],MATCH(S41,Wsad_Ofertowy[Kod],0),'Generowanie podsumowania zam'!$U$1)} -> 13.29 | R44: =I42*G44*O41 -> 0
E45: =INDEX(Wsad_Ofertowy[#Data],MATCH(S41,Wsad_Ofertowy[Kod],0),5) -> 5907702531755 | G45: cena za szt. | R45: wartość zamawiana
J50: Dane logistyczne | N50: Ilość zamawianych
N51: opakowań
O52: 0 | S52: CZNI0702
I53: =INDEX(Wsad_Ofertowy[#Data],MATCH(S52,Wsad_Ofertowy[Kod],0),21) -> 4 | J53: sztuk w opakowaniu
D55: =INDEX(Wsad_Ofertowy[#Data],MATCH(S52,Wsad_Ofertowy[Kod],0),4) -> L 2710 mama/zł | G55: {=INDEX(Wsad_Ofertowy[#Data],MATCH(S52,Wsad_Ofertowy[Kod],0),'Generowanie podsumowania zam'!$U$1)} -> 13.29 | R55: =I53*G55*O52 -> 0
E56: =INDEX(Wsad_Ofertowy[#Data],MATCH(S52,Wsad_Ofertowy[Kod],0),5) -> 5907702531748 | G56: cena za szt. | R56: wartość zamawiana
J61: Dane logistyczne | N61: Ilość zamawianych
N62: opakowań
O63: 0 | S63: CZNI0748
I64: =INDEX(Wsad_Ofertowy[#Data],MATCH(S63,Wsad_Ofertowy[Kod],0),21) -> 4 | J64: sztuk w opakowaniu
D66: =INDEX(Wsad_Ofertowy[#Data],MATCH(S63,Wsad_Ofertowy[Kod],0),4) -> L 2710 tata SR | G66: {=INDEX(Wsad_Ofertowy[#Data],MATCH(S63,Wsad_Ofertowy[Kod],0),'Generowanie podsumowania zam'!$U$1)} -> 13.29 | R66: =I64*G66*O63 -> 0
E67: =INDEX(Wsad_Ofertowy[#Data],MATCH(S63,Wsad_Ofertowy[Kod],0),5) -> 5907702531823 | G67: cena za szt. | R67: wartość zamawiana
J72: Dane logistyczne | N72: Ilość zamawianych
N73: opakowań
O74: 0 | S74: CZNI0749
I75: =INDEX(Wsad_Ofertowy[#Data],MATCH(S74,Wsad_Ofertowy[Kod],0),21) -> 4 | J75: sztuk w opakowaniu
...

Sheet lampiony
J6: Dane logistyczne | N6: Ilość zamawianych
N7: opakowań
O8: 0 | S8: IMPA0007
I9: =INDEX(Wsad_Ofertowy[#Data],MATCH(S8,Wsad_Ofertowy[Kod],0),21) -> 8 | J9: sztuk w opakowaniu
D11: =INDEX(Wsad_Ofertowy[#Data],MATCH(S8,Wsad_Ofertowy[Kod],0),4) -> Imp Lampion gracja mała mix biała | G11: {=INDEX(Wsad_Ofertowy[#Data],MATCH(S8,Wsad_Ofertowy[Kod],0),'Generowanie podsumowania zam'!$U$1)} -> 28.75 | R11: =I9*G11*O8 -> 0
E12: =INDEX(Wsad_Ofertowy[#Data],MATCH(S8,Wsad_Ofertowy[Kod],0),5) -> 5907702527826 | G12: cena za szt. | R12: wartość zamawiana
J17: Dane logistyczne | N17: Ilość zamawianych
N18: opakowań
O19: 0 | S19: SMAL0031
I20: =INDEX(Wsad_Ofertowy[#Data],MATCH(S19,Wsad_Ofertowy[Kod],0),21) -> 6 | J20: sztuk w opakowaniu
D22: =INDEX(Wsad_Ofertowy[#Data],MATCH(S19,Wsad_Ofertowy[Kod],0),4) -> Kapliczka Prosta krzyż lusto MIX-P. | G22: {=INDEX(Wsad_Ofertowy[#Data],MATCH(S19,Wsad_Ofertowy[Kod],0),'Generowanie podsumowania zam'!$U$1)} -> 22.95 | R22: =I20*G22*O19 -> 0
E23: =INDEX(Wsad_Ofertowy[#Data],MATCH(S19,Wsad_Ofertowy[Kod],0),5) -> 5907702534237 | G23: cena za szt. | R23: wartość zamawiana
J28: Dane logistyczne | N28: Ilość zamawianych
N29: opakowań
O30: 0 | S30: IMPA0101
I31: =INDEX(Wsad_Ofertowy[#Data],MATCH(S30,Wsad_Ofertowy[Kod],0),21) -> 8 | J31: sztuk w opakowaniu
D33: =INDEX(Wsad_Ofertowy[#Data],MATCH(S30,Wsad_Ofertowy[Kod],0),4) -> Lampion Drzewo SR | G33: {=INDEX(Wsad_Ofertowy[#Data],MATCH(S30,Wsad_Ofertowy[Kod],0),'Generowanie podsumowania zam'!$U$1)} -> 39.99 | R33: =I31*G33*O30 -> 0
E34: =INDEX(Wsad_Ofertowy[#Data],MATCH(S30,Wsad_Ofertowy[Kod],0),5) -> 5907702535524 | G34: cena za szt. | R34: wartość zamawiana
J39: Dane logistyczne | N39: Ilość zamawianych
N40: opakowań
O41: 0 | S41: IMPA0102
I42: =INDEX(Wsad_Ofertowy[#Data],MATCH(S41,Wsad_Ofertowy[Kod],0),21) -> 8 | J42: sztuk w opakowaniu
D44: =INDEX(Wsad_Ofertowy[#Data],MATCH(S41,Wsad_Ofertowy[Kod],0),4) -> Lampion Drzewo zl | G44: {=INDEX(Wsad_Ofertowy[#Data],MATCH(S41,Wsad_Ofertowy[Kod],0),'Generowanie podsumowania zam'!$U$1)} -> 39.99 | R44: =I42*G44*O41 -> 0
E45: =INDEX(Wsad_Ofertowy[#Data],MATCH(S41,Wsad_Ofertowy[Kod],0),5) -> 5907702535531 | G45: cena za szt. | R45: wartość zamawiana
J50: Dane logistyczne | N50: Ilość zamawianych
N51: opakowań
O52: 0 | S52: IMPA0124
I53: =INDEX(Wsad_Ofertowy[#Data],MATCH(S52,Wsad_Ofertowy[Kod],0),21) -> 8 | J53: sztuk w opakowaniu
D55: =INDEX(Wsad_Ofertowy[#Data],MATCH(S52,Wsad_Ofertowy[Kod],0),4) -> Lampion Gracja mała MIX-P. | G55: {=INDEX(Wsad_Ofertowy[#Data],MATCH(S52,Wsad_Ofertowy[Kod],0),'Generowanie podsumowania zam'!$U$1)} -> 28.98 | R55: =I53*G55*O52 -> 0
E56: =INDEX(Wsad_Ofertowy[#Data],MATCH(S52,Wsad_Ofertowy[Kod],0),5) -> 5907702534183 | G56: cena za szt. | R56: wartość zamawiana
J61: Dane logistyczne | N61: Ilość zamawianych
N62: opakowań
O63: 0 | S63: SILV0013
I64: =INDEX(Wsad_Ofertowy[#Data],MATCH(S63,Wsad_Ofertowy[Kod],0),21) -> 6 | J64: sztuk w opakowaniu
D66: =INDEX(Wsad_Ofertowy[#Data],MATCH(S63,Wsad_Ofertowy[Kod],0),4) -> Lampion Kwadrat Biały | G66: {=INDEX(Wsad_Ofertowy[#Data],MATCH(S63,Wsad_Ofertowy[Kod],0),'Generowanie podsumowania zam'!$U$1)} -> 25.95 | R66: =I64*G66*O63 -> 0
E67: =INDEX(Wsad_Ofertowy[#Data],MATCH(S63,Wsad_Ofertowy[Kod],0),5) -> 5907702534213 | G67: cena za szt. | R67: wartość zamawiana
J72: Dane logistyczne | N72: Ilość zamawianych
N73: opakowań
O74: 0 | S74: SILV0014
I75: =INDEX(Wsad_Ofertowy[#Data],MATCH(S74,Wsad_Ofertowy[Kod],0),21) -> 6 | J75: sztuk w opakowaniu
...

Sheet Znicze_led
J6: Dane logistyczne | N6: Ilość zamawianych
N7: opakowań
O8: 0 | S8: CZNI1310
I9: =INDEX(Wsad_Ofertowy[#Data],MATCH(S8,Wsad_Ofertowy[Kod],0),21) -> 8 | J9: sztuk w opakowaniu
D11: =INDEX(Wsad_Ofertowy[#Data],MATCH(S8,Wsad_Ofertowy[Kod],0),4) -> Znicz Z 430 solar | G11: {=INDEX(Wsad_Ofertowy[#Data],MATCH(S8,Wsad_Ofertowy[Kod],0),'Generowanie podsumowania zam'!$U$1)} -> 14.73 | R11: =I9*G11*O8 -> 0
E12: =INDEX(Wsad_Ofertowy[#Data],MATCH(S8,Wsad_Ofertowy[Kod],0),5) -> 5907702537580 | G12: cena za szt. | R12: wartość zamawiana
J17: Dane logistyczne | N17: Ilość zamawianych
N18: opakowań
O19: 0 | S19: CZNI1311
I20: =INDEX(Wsad_Ofertowy[#Data],MATCH(S19,Wsad_Ofertowy[Kod],0),21) -> 6 | J20: sztuk w opakowaniu
D22: =INDEX(Wsad_Ofertowy[#Data],MATCH(S19,Wsad_Ofertowy[Kod],0),4) -> Znicz Z 535 solar | G22: {=INDEX(Wsad_Ofertowy[#Data],MATCH(S19,Wsad_Ofertowy[Kod],0),'Generowanie podsumowania zam'!$U$1)} -> 14.2 | R22: =I20*G22*O19 -> 0
E23: =INDEX(Wsad_Ofertowy[#Data],MATCH(S19,Wsad_Ofertowy[Kod],0),5) -> 5907702537573 | G23: cena za szt. | R23: wartość zamawiana

Sheet wkłady
J6: Dane logistyczne | N6: Ilość zamawianych
N7: opakowań
O8: 0 | S8: CWKZ0023
I9: =INDEX(Wsad_Ofertowy[#Data],MATCH(S8,Wsad_Ofertowy[Kod],0),21) -> 20 | J9: sztuk w opakowaniu
D11: =INDEX(Wsad_Ofertowy[#Data],MATCH(S8,Wsad_Ofertowy[Kod],0),4) -> Wk CEiM Eko-oil nr4 4D | G11: {=INDEX(Wsad_Ofertowy[#Data],MATCH(S8,Wsad_Ofertowy[Kod],0),'Generowanie podsumowania zam'!$U$1)} -> 2.69 | R11: =I9*G11*O8 -> 0
E12: =INDEX(Wsad_Ofertowy[#Data],MATCH(S8,Wsad_Ofertowy[Kod],0),5) -> 5907702521596 | G12: cena za szt. | R12: wartość zamawiana
J17: Dane logistyczne | N17: Ilość zamawianych
N18: opakowań
O19: 0 | S19: CWKZ0024
I20: =INDEX(Wsad_Ofertowy[#Data],MATCH(S19,Wsad_Ofertowy[Kod],0),21) -> 16 | J20: sztuk w opakowaniu
D22: =INDEX(Wsad_Ofertowy[#Data],MATCH(S19,Wsad_Ofertowy[Kod],0),4) -> Wk CEiM Eko-oil nr5 5D | G22: {=INDEX(Wsad_Ofertowy[#Data],MATCH(S19,Wsad_Ofertowy[Kod],0),'Generowanie podsumowania zam'!$U$1)} -> 3.39 | R22: =I20*G22*O19 -> 0
E23: =INDEX(Wsad_Ofertowy[#Data],MATCH(S19,Wsad_Ofertowy[Kod],0),5) -> 5907702521619 | G23: cena za szt. | R23: wartość zamawiana
J28: Dane logistyczne | N28: Ilość zamawianych
N29: opakowań
O30: 0 | S30: CWKZ0026
I31: =INDEX(Wsad_Ofertowy[#Data],MATCH(S30,Wsad_Ofertowy[Kod],0),21) -> 16 | J31: sztuk w opakowaniu
D33: =INDEX(Wsad_Ofertowy[#Data],MATCH(S30,Wsad_Ofertowy[Kod],0),4) -> Wk CEiM Eko-oil nr6 6D | G33: {=INDEX(Wsad_Ofertowy[#Data],MATCH(S30,Wsad_Ofertowy[Kod],0),'Generowanie podsumowania zam'!$U$1)} -> 4.29 | R33: =I31*G33*O30 -> 0
E34: =INDEX(Wsad_Ofertowy[#Data],MATCH(S30,Wsad_Ofertowy[Kod],0),5) -> 5907702521626 | G34: cena za szt. | R34: wartość zamawiana
J39: Dane logistyczne | N39: Ilość zamawianych
N40: opakowań
O41: 0 | S41: CWKZ0027
I42: =INDEX(Wsad_Ofertowy[#Data],MATCH(S41,Wsad_Ofertowy[Kod],0),21) -> 20 | J42: sztuk w opakowaniu
D44: =INDEX(Wsad_Ofertowy[#Data],MATCH(S41,Wsad_Ofertowy[Kod],0),4) -> Wk CEiM rozsuwany 3 | G44: {=INDEX(Wsad_Ofertowy[#Data],MATCH(S41,Wsad_Ofertowy[Kod],0),'Generowanie podsumowania zam'!$U$1)} -> 2.89 | R44: =I42*G44*O41 -> 0
E45: =INDEX(Wsad_Ofertowy[#Data],MATCH(S41,Wsad_Ofertowy[Kod],0),5) -> 5907702523279 | G45: cena za szt. | R45: wartość zamawiana
J50: Dane logistyczne | N50: Ilość zamawianych
N51: opakowań
O52: 0 | S52: CWKZ0033
I53: =INDEX(Wsad_Ofertowy[#Data],MATCH(S52,Wsad_Ofertowy[Kod],0),21) -> 20 | J53: sztuk w opakowaniu
D55: =INDEX(Wsad_Ofertowy[#Data],MATCH(S52,Wsad_Ofertowy[Kod],0),4) -> Wk CEiM zniczowy 3 | G55: {=INDEX(Wsad_Ofertowy[#Data],MATCH(S52,Wsad_Ofertowy[Kod],0),'Generowanie podsumowania zam'!$U$1)} -> 2.19 | R55: =I53*G55*O52 -> 0
E56: =INDEX(Wsad_Ofertowy[#Data],MATCH(S52,Wsad_Ofertowy[Kod],0),5) -> 5907702509860 | G56: cena za szt. | R56: wartość zamawiana
J61: Dane logistyczne | N61: Ilość zamawianych
N62: opakowań
O63: 0 | S63: CWKZ0034
I64: =INDEX(Wsad_Ofertowy[#Data],MATCH(S63,Wsad_Ofertowy[Kod],0),21) -> 20 | J64: sztuk w opakowaniu
D66: =INDEX(Wsad_Ofertowy[#Data],MATCH(S63,Wsad_Ofertowy[Kod],0),4) -> Wk CEiM zniczowy 4 | G66: {=INDEX(Wsad_Ofertowy[#Data],MATCH(S63,Wsad_Ofertowy[Kod],0),'Generowanie podsumowania zam'!$U$1)} -> 2.82 | R66: =I64*G66*O63 -> 0
E67: =INDEX(Wsad_Ofertowy[#Data],MATCH(S63,Wsad_Ofertowy[Kod],0),5) -> 5907702509877 | G67: cena za szt. | R67: wartość zamawiana
J72: Dane logistyczne | N72: Ilość zamawianych
N73: opakowań
O74: 0 | S74: CWKZ0035
I75: =INDEX(Wsad_Ofertowy[#Data],MATCH(S74,Wsad_Ofertowy[Kod],0),21) -> 20 | J75: sztuk w opakowaniu
...

Sheet wkłady_led
J6: Dane logistyczne | N6: Ilość zamawianych
N7: opakowań
O8: 0 | S8: ASSA0031
I9: =INDEX(Wsad_Ofertowy[#Data],MATCH(S8,Wsad_Ofertowy[Kod],0),21) -> 12 | J9: sztuk w opakowaniu
D11: =INDEX(Wsad_Ofertowy[#Data],MATCH(S8,Wsad_Ofertowy[Kod],0),4) -> Ass Świetlik S1 - biały | G11: {=INDEX(Wsad_Ofertowy[#Data],MATCH(S8,Wsad_Ofertowy[Kod],0),'Generowanie podsumowania zam'!$U$1)} -> 3.35 | R11: =I9*G11*O8 -> 0
E12: =INDEX(Wsad_Ofertowy[#Data],MATCH(S8,Wsad_Ofertowy[Kod],0),5) -> 5907646175725 | G12: cena za szt. | R12: wartość zamawiana
J17: Dane logistyczne | N17: Ilość zamawianych
N18: opakowań
O19: 0 | S19: ASSA0032
I20: =INDEX(Wsad_Ofertowy[#Data],MATCH(S19,Wsad_Ofertowy[Kod],0),21) -> 12 | J20: sztuk w opakowaniu
D22: =INDEX(Wsad_Ofertowy[#Data],MATCH(S19,Wsad_Ofertowy[Kod],0),4) -> Ass Świetlik S1 - czerwony | G22: {=INDEX(Wsad_Ofertowy[#Data],MATCH(S19,Wsad_Ofertowy[Kod],0),'Generowanie podsumowania zam'!$U$1)} -> 3.35 | R22: =I20*G22*O19 -> 0
E23: =INDEX(Wsad_Ofertowy[#Data],MATCH(S19,Wsad_Ofertowy[Kod],0),5) -> 5907646175725 | G23: cena za szt. | R23: wartość zamawiana
J28: Dane logistyczne | N28: Ilość zamawianych
N29: opakowań
O30: 0 | S30: ASSA0033
I31: =INDEX(Wsad_Ofertowy[#Data],MATCH(S30,Wsad_Ofertowy[Kod],0),21) -> 12 | J31: sztuk w opakowaniu
D33: =INDEX(Wsad_Ofertowy[#Data],MATCH(S30,Wsad_Ofertowy[Kod],0),4) -> Ass Świetlik S1 - fioletowy | G33: {=INDEX(Wsad_Ofertowy[#Data],MATCH(S30,Wsad_Ofertowy[Kod],0),'Generowanie podsumowania zam'!$U$1)} -> 3.35 | R33: =I31*G33*O30 -> 0
E34: =INDEX(Wsad_Ofertowy[#Data],MATCH(S30,Wsad_Ofertowy[Kod],0),5) -> 5907646175725 | G34: cena za szt. | R34: wartość zamawiana
J39: Dane logistyczne | N39: Ilość zamawianych
N40: opakowań
O41: 0 | S41: ASSA0034
I42: =INDEX(Wsad_Ofertowy[#Data],MATCH(S41,Wsad_Ofertowy[Kod],0),21) -> 24 | J42: sztuk w opakowaniu
D44: =INDEX(Wsad_Ofertowy[#Data],MATCH(S41,Wsad_Ofertowy[Kod],0),4) -> Ass Świetlik S1 - mix | G44: {=INDEX(Wsad_Ofertowy[#Data],MATCH(S41,Wsad_Ofertowy[Kod],0),'Generowanie podsumowania zam'!$U$1)} -> 3.35 | R44: =I42*G44*O41 -> 0
E45: =INDEX(Wsad_Ofertowy[#Data],MATCH(S41,Wsad_Ofertowy[Kod],0),5) -> 5907646175725 | G45: cena za szt. | R45: wartość zamawiana
J50: Dane logistyczne | N50: Ilość zamawianych
N51: opakowań
O52: 0 | S52: ASSA0035
I53: =INDEX(Wsad_Ofertowy[#Data],MATCH(S52,Wsad_Ofertowy[Kod],0),21) -> 12 | J53: sztuk w opakowaniu
D55: =INDEX(Wsad_Ofertowy[#Data],MATCH(S52,Wsad_Ofertowy[Kod],0),4) -> Ass Świetlik S1 - niebieski | G55: {=INDEX(Wsad_Ofertowy[#Data],MATCH(S52,Wsad_Ofertowy[Kod],0),'Generowanie podsumowania zam'!$U$1)} -> 3.35 | R55: =I53*G55*O52 -> 0
E56: =INDEX(Wsad_Ofertowy[#Data],MATCH(S52,Wsad_Ofertowy[Kod],0),5) -> 5907646175725 | G56: cena za szt. | R56: wartość zamawiana
J61: Dane logistyczne | N61: Ilość zamawianych
N62: opakowań
O63: 0 | S63: ASSA0036
I64: =INDEX(Wsad_Ofertowy[#Data],MATCH(S63,Wsad_Ofertowy[Kod],0),21) -> 12 | J64: sztuk w opakowaniu
D66: =INDEX(Wsad_Ofertowy[#Data],MATCH(S63,Wsad_Ofertowy[Kod],0),4) -> Ass Świetlik S1 - pomarańcz | G66: {=INDEX(Wsad_Ofertowy[#Data],MATCH(S63,Wsad_Ofertowy[Kod],0),'Generowanie podsumowania zam'!$U$1)} -> 3.35 | R66: =I64*G66*O63 -> 0
E67: =INDEX(Wsad_Ofertowy[#Data],MATCH(S63,Wsad_Ofertowy[Kod],0),5) -> 5907646175725 | G67: cena za szt. | R67: wartość zamawiana
J72: Dane logistyczne | N72: Ilość zamawianych
N73: opakowań
O74: 0 | S74: ASSA0037
I75: =INDEX(Wsad_Ofertowy[#Data],MATCH(S74,Wsad_Ofertowy[Kod],0),21) -> 12 | J75: sztuk w opakowaniu
...

Sheet Zapalarki
D4: #VALUE!
J6: Dane logistyczne | N6: Ilość zamawianych
N7: opakowań
O8: 0 | S8: KOST0030
I9: =INDEX(Wsad_Ofertowy[#Data],MATCH(S8,Wsad_Ofertowy[Kod],0),21) -> 12 | J9: sztuk w opakowaniu
D11: =INDEX(Wsad_Ofertowy[#Data],MATCH(S8,Wsad_Ofertowy[Kod],0),4) -> Kos gaz do zapalniczek 250 ml | G11: {=INDEX(Wsad_Ofertowy[#Data],MATCH(S8,Wsad_Ofertowy[Kod],0),'Generowanie podsumowania zam'!$U$1)} -> 4.69 | R11: =I9*G11*O8 -> 0
E12: =INDEX(Wsad_Ofertowy[#Data],MATCH(S8,Wsad_Ofertowy[Kod],0),5) -> 5907589849127 | G12: cena za szt. | R12: wartość zamawiana
D15: #VALUE!
J17: Dane logistyczne | N17: Ilość zamawianych
N18: opakowań
O19: 0 | S19: KOST0001
I20: =INDEX(Wsad_Ofertowy[#Data],MATCH(S19,Wsad_Ofertowy[Kod],0),21) -> 12 | J20: sztuk w opakowaniu
D22: =INDEX(Wsad_Ofertowy[#Data],MATCH(S19,Wsad_Ofertowy[Kod],0),4) -> Kos gaz do zapalniczek 90 ml | G22: {=INDEX(Wsad_Ofertowy[#Data],MATCH(S19,Wsad_Ofertowy[Kod],0),'Generowanie podsumowania zam'!$U$1)} -> 2.79 | R22: =I20*G22*O19 -> 0
E23: =INDEX(Wsad_Ofertowy[#Data],MATCH(S19,Wsad_Ofertowy[Kod],0),5) -> 5907589849110 | G23: cena za szt. | R23: wartość zamawiana
D26: #VALUE!
J28: Dane logistyczne | N28: Ilość zamawianych
N29: opakowań
O30: 0 | S30: KOST0009
I31: =INDEX(Wsad_Ofertowy[#Data],MATCH(S30,Wsad_Ofertowy[Kod],0),21) -> 25 | J31: sztuk w opakowaniu
D33: =INDEX(Wsad_Ofertowy[#Data],MATCH(S30,Wsad_Ofertowy[Kod],0),4) -> Kos Zapalarka Antenka | G33: {=INDEX(Wsad_Ofertowy[#Data],MATCH(S30,Wsad_Ofertowy[Kod],0),'Generowanie podsumowania zam'!$U$1)} -> 1.94 | R33: =I31*G33*O30 -> 0
E34: =INDEX(Wsad_Ofertowy[#Data],MATCH(S30,Wsad_Ofertowy[Kod],0),5) -> 5907589849158 | G34: cena za szt. | R34: wartość zamawiana
D37: #VALUE!
J39: Dane logistyczne | N39: Ilość zamawianych
N40: opakowań
O41: 0 | S41: KOST0010
I42: =INDEX(Wsad_Ofertowy[#Data],MATCH(S41,Wsad_Ofertowy[Kod],0),21) -> 16 | J42: sztuk w opakowaniu
D44: =INDEX(Wsad_Ofertowy[#Data],MATCH(S41,Wsad_Ofertowy[Kod],0),4) -> Kos Zapalarka Długa 28 | G44: {=INDEX(Wsad_Ofertowy[#Data],MATCH(S41,Wsad_Ofertowy[Kod],0),'Generowanie podsumowania zam'!$U$1)} -> 2.99 | R44: =I42*G44*O41 -> 0
E45: =INDEX(Wsad_Ofertowy[#Data],MATCH(S41,Wsad_Ofertowy[Kod],0),5) -> 5907589849134 | G45: cena za szt. | R45: wartość zamawiana
D48: #VALUE!
J50: Dane logistyczne | N50: Ilość zamawianych
N51: opakowań
O52: 0 | S52: KOST0011
I53: =INDEX(Wsad_Ofertowy[#Data],MATCH(S52,Wsad_Ofertowy[Kod],0),21) -> 25 | J53: sztuk w opakowaniu
D55: =INDEX(Wsad_Ofertowy[#Data],MATCH(S52,Wsad_Ofertowy[Kod],0),4) -> Kos Zapalarka krótka | G55: {=INDEX(Wsad_Ofertowy[#Data],MATCH(S52,Wsad_Ofertowy[Kod],0),'Generowanie podsumowania zam'!$U$1)} -> 1.65 | R55: =I53*G55*O52 -> 0
E56: =INDEX(Wsad_Ofertowy[#Data],MATCH(S52,Wsad_Ofertowy[Kod],0),5) -> 5907589849141 | G56: cena za szt. | R56: wartość zamawiana
J61: Dane logistyczne | N61: Ilość zamawianych
N62: opakowań
O63: 0 | S63: KOST0012
I64: =INDEX(Wsad_Ofertowy[#Data],MATCH(S63,Wsad_Ofertowy[Kod],0),21) -> 25 | J64: sztuk w opakowaniu
D66: =INDEX(Wsad_Ofertowy[#Data],MATCH(S63,Wsad_Ofertowy[Kod],0),4) -> Kos Zapalarka krótka żarowa | G66: {=INDEX(Wsad_Ofertowy[#Data],MATCH(S63,Wsad_Ofertowy[Kod],0),'Generowanie podsumowania zam'!$U$1)} -> 1.79 | R66: =I64*G66*O63 -> 0
...

Sheet Podsumowanie zamówienia
E4: Wartość całości zamówienia netto | H4: =SUM(H8:H1048576) -> 0
D7: L.p. | E7: Nazwa | F7: Ilość op. | G7: Cena netto za szt. | H7: Wartość netto | J7: =MAX(Generowanie_Zamówienia[Zliczanie]) -> 0
D8: 1 | E8: =IF(Podsumowanie_[[#This Row],[L.p.]]<=$J$7,INDEX(Generowanie_Zamówienia[],MATCH(Podsumowanie_[[#This Row],[L.p.]],Generowanie_Zamówienia[Zliczanie],0),9),"") | F8: =IF(Podsumowanie_[[#This Row],[L.p.]]<=$J$7,INDEX(Generowanie_Zamówienia[],MATCH(Podsumowanie_[[#This Row],[L.p.]],Generowanie_Zamówienia[Zliczanie],0),2),"") | G8: =IF(Podsumowanie_[[#This Row],[L.p.]]<=$J$7,INDEX(Generowanie_Zamówienia[],MATCH(Podsumowanie_[[#This Row],[L.p.]],Generowanie_Zamówienia[Zliczanie],0),4),"") | H8: =IFERROR(Podsumowanie_[[#This Row],[Ilość op.]]*Podsumowanie_[[#This Row],[Cena netto za szt.]]*INDEX(Generowanie_Zamówienia[],MATCH(Podsumowanie_[[#This Row],[L.p.]],Generowanie_Zamówienia[Zliczanie],0),3),"")
D9: 2 | E9: =IF(Podsumowanie_[[#This Row],[L.p.]]<=$J$7,INDEX(Generowanie_Zamówienia[],MATCH(Podsumowanie_[[#This Row],[L.p.]],Generowanie_Zamówienia[Zliczanie],0),9),"") | F9: =IF(Podsumowanie_[[#This Row],[L.p.]]<=$J$7,INDEX(Generowanie_Zamówienia[],MATCH(Podsumowanie_[[#This Row],[L.p.]],Generowanie_Zamówienia[Zliczanie],0),2),"") | G9: =IF(Podsumowanie_[[#This Row],[L.p.]]<=$J$7,INDEX(Generowanie_Zamówienia[],MATCH(Podsumowanie_[[#This Row],[L.p.]],Generowanie_Zamówienia[Zliczanie],0),4),"") | H9: =IFERROR(Podsumowanie_[[#This Row],[Ilość op.]]*Podsumowanie_[[#This Row],[Cena netto za szt.]]*INDEX(Generowanie_Zamówienia[],MATCH(Podsumowanie_[[#This Row],[L.p.]],Generowanie_Zamówienia[Zliczanie],0),3),"")
D10: 3 | E10: =IF(Podsumowanie_[[#This Row],[L.p.]]<=$J$7,INDEX(Generowanie_Zamówienia[],MATCH(Podsumowanie_[[#This Row],[L.p.]],Generowanie_Zamówienia[Zliczanie],0),9),"") | F10: =IF(Podsumowanie_[[#This Row],[L.p.]]<=$J$7,INDEX(Generowanie_Zamówienia[],MATCH(Podsumowanie_[[#This Row],[L.p.]],Generowanie_Zamówienia[Zliczanie],0),2),"") | G10: =IF(Podsumowanie_[[#This Row],[L.p.]]<=$J$7,INDEX(Generowanie_Zamówienia[],MATCH(Podsumowanie_[[#This Row],[L.p.]],Generowanie_Zamówienia[Zliczanie],0),4),"") | H10: =IFERROR(Podsumowanie_[[#This Row],[Ilość op.]]*Podsumowanie_[[#This Row],[Cena netto za szt.]]*INDEX(Generowanie_Zamówienia[],MATCH(Podsumowanie_[[#This Row],[L.p.]],Generowanie_Zamówienia[Zliczanie],0),3),"")
D11: 4 | E11: =IF(Podsumowanie_[[#This Row],[L.p.]]<=$J$7,INDEX(Generowanie_Zamówienia[],MATCH(Podsumowanie_[[#This Row],[L.p.]],Generowanie_Zamówienia[Zliczanie],0),9),"") | F11: =IF(Podsumowanie_[[#This Row],[L.p.]]<=$J$7,INDEX(Generowanie_Zamówienia[],MATCH(Podsumowanie_[[#This Row],[L.p.]],Generowanie_Zamówienia[Zliczanie],0),2),"") | G11: =IF(Podsumowanie_[[#This Row],[L.p.]]<=$J$7,INDEX(Generowanie_Zamówienia[],MATCH(Podsumowanie_[[#This Row],[L.p.]],Generowanie_Zamówienia[Zliczanie],0),4),"") | H11: =IFERROR(Podsumowanie_[[#This Row],[Ilość op.]]*Podsumowanie_[[#This Row],[Cena netto za szt.]]*INDEX(Generowanie_Zamówienia[],MATCH(Podsumowanie_[[#This Row],[L.p.]],Generowanie_Zamówienia[Zliczanie],0),3),"")
D12: 5 | E12: =IF(Podsumowanie_[[#This Row],[L.p.]]<=$J$7,INDEX(Generowanie_Zamówienia[],MATCH(Podsumowanie_[[#This Row],[L.p.]],Generowanie_Zamówienia[Zliczanie],0),9),"") | F12: =IF(Podsumowanie_[[#This Row],[L.p.]]<=$J$7,INDEX(Generowanie_Zamówienia[],MATCH(Podsumowanie_[[#This Row],[L.p.]],Generowanie_Zamówienia[Zliczanie],0),2),"") | G12: =IF(Podsumowanie_[[#This Row],[L.p.]]<=$J$7,INDEX(Generowanie_Zamówienia[],MATCH(Podsumowanie_[[#This Row],[L.p.]],Generowanie_Zamówienia[Zliczanie],0),4),"") | H12: =IFERROR(Podsumowanie_[[#This Row],[Ilość op.]]*Podsumowanie_[[#This Row],[Cena netto za szt.]]*INDEX(Generowanie_Zamówienia[],MATCH(Podsumowanie_[[#This Row],[L.p.]],Generowanie_Zamówienia[Zliczanie],0),3),"")
D13: 6 | E13: =IF(Podsumowanie_[[#This Row],[L.p.]]<=$J$7,INDEX(Generowanie_Zamówienia[],MATCH(Podsumowanie_[[#This Row],[L.p.]],Generowanie_Zamówienia[Zliczanie],0),9),"") | F13: =IF(Podsumowanie_[[#This Row],[L.p.]]<=$J$7,INDEX(Generowanie_Zamówienia[],MATCH(Podsumowanie_[[#This Row],[L.p.]],Generowanie_Zamówienia[Zliczanie],0),2),"") | G13: =IF(Podsumowanie_[[#This Row],[L.p.]]<=$J$7,INDEX(Generowanie_Zamówienia[],MATCH(Podsumowanie_[[#This Row],[L.p.]],Generowanie_Zamówienia[Zliczanie],0),4),"") | H13: =IFERROR(Podsumowanie_[[#This Row],[Ilość op.]]*Podsumowanie_[[#This Row],[Cena netto za szt.]]*INDEX(Generowanie_Zamówienia[],MATCH(Podsumowanie_[[#This Row],[L.p.]],Generowanie_Zamówienia[Zliczanie],0),3),"")
D14: 7 | E14: =IF(Podsumowanie_[[#This Row],[L.p.]]<=$J$7,INDEX(Generowanie_Zamówienia[],MATCH(Podsumowanie_[[#This Row],[L.p.]],Generowanie_Zamówienia[Zliczanie],0),9),"") | F14: =IF(Podsumowanie_[[#This Row],[L.p.]]<=$J$7,INDEX(Generowanie_Zamówienia[],MATCH(Podsumowanie_[[#This Row],[L.p.]],Generowanie_Zamówienia[Zliczanie],0),2),"") | G14: =IF(Podsumowanie_[[#This Row],[L.p.]]<=$J$7,INDEX(Generowanie_Zamówienia[],MATCH(Podsumowanie_[[#This Row],[L.p.]],Generowanie_Zamówienia[Zliczanie],0),4),"") | H14: =IFERROR(Podsumowanie_[[#This Row],[Ilość op.]]*Podsumowanie_[[#This Row],[Cena netto za szt.]]*INDEX(Generowanie_Zamówienia[],MATCH(Podsumowanie_[[#This Row],[L.p.]],Generowanie_Zamówienia[Zliczanie],0),3),"")
D15: 8 | E15: =IF(Podsumowanie_[[#This Row],[L.p.]]<=$J$7,INDEX(Generowanie_Zamówienia[],MATCH(Podsumowanie_[[#This Row],[L.p.]],Generowanie_Zamówienia[Zliczanie],0),9),"") | F15: =IF(Podsumowanie_[[#This Row],[L.p.]]<=$J$7,INDEX(Generowanie_Zamówienia[],MATCH(Podsumowanie_[[#This Row],[L.p.]],Generowanie_Zamówienia[Zliczanie],0),2),"") | G15: =IF(Podsumowanie_[[#This Row],[L.p.]]<=$J$7,INDEX(Generowanie_Zamówienia[],MATCH(Podsumowanie_[[#This Row],[L.p.]],Generowanie_Zamówienia[Zliczanie],0),4),"") | H15: =IFERROR(Podsumowanie_[[#This Row],[Ilość op.]]*Podsumowanie_[[#This Row],[Cena netto za szt.]]*INDEX(Generowanie_Zamówienia[],MATCH(Podsumowanie_[[#This Row],[L.p.]],Generowanie_Zamówienia[Zliczanie],0),3),"")
D16: 9 | E16: =IF(Podsumowanie_[[#This Row],[L.p.]]<=$J$7,INDEX(Generowanie_Zamówienia[],MATCH(Podsumowanie_[[#This Row],[L.p.]],Generowanie_Zamówienia[Zliczanie],0),9),"") | F16: =IF(Podsumowanie_[[#This Row],[L.p.]]<=$J$7,INDEX(Generowanie_Zamówienia[],MATCH(Podsumowanie_[[#This Row],[L.p.]],Generowanie_Zamówienia[Zliczanie],0),2),"") | G16: =IF(Podsumowanie_[[#This Row],[L.p.]]<=$J$7,INDEX(Generowanie_Zamówienia[],MATCH(Podsumowanie_[[#This Row],[L.p.]],Generowanie_Zamówienia[Zliczanie],0),4),"") | H16: =IFERROR(Podsumowanie_[[#This Row],[Ilość op.]]*Podsumowanie_[[#This Row],[Cena netto za szt.]]*INDEX(Generowanie_Zamówienia[],MATCH(Podsumowanie_[[#This Row],[L.p.]],Generowanie_Zamówienia[Zliczanie],0),3),"")
D17: 10 | E17: =IF(Podsumowanie_[[#This Row],[L.p.]]<=$J$7,INDEX(Generowanie_Zamówienia[],MATCH(Podsumowanie_[[#This Row],[L.p.]],Generowanie_Zamówienia[Zliczanie],0),9),"") | F17: =IF(Podsumowanie_[[#This Row],[L.p.]]<=$J$7,INDEX(Generowanie_Zamówienia[],MATCH(Podsumowanie_[[#This Row],[L.p.]],Generowanie_Zamówienia[Zliczanie],0),2),"") | G17: =IF(Podsumowanie_[[#This Row],[L.p.]]<=$J$7,INDEX(Generowanie_Zamówienia[],MATCH(Podsumowanie_[[#This Row],[L.p.]],Generowanie_Zamówienia[Zliczanie],0),4),"") | H17: =IFERROR(Podsumowanie_[[#This Row],[Ilość op.]]*Podsumowanie_[[#This Row],[Cena netto za szt.]]*INDEX(Generowanie_Zamówienia[],MATCH(Podsumowanie_[[#This Row],[L.p.]],Generowanie_Zamówienia[Zliczanie],0),3),"")
D18: 11 | E18: =IF(Podsumowanie_[[#This Row],[L.p.]]<=$J$7,INDEX(Generowanie_Zamówienia[],MATCH(Podsumowanie_[[#This Row],[L.p.]],Generowanie_Zamówienia[Zliczanie],0),9),"") | F18: =IF(Podsumowanie_[[#This Row],[L.p.]]<=$J$7,INDEX(Generowanie_Zamówienia[],MATCH(Podsumowanie_[[#This Row],[L.p.]],Generowanie_Zamówienia[Zliczanie],0),2),"") | G18: =IF(Podsumowanie_[[#This Row],[L.p.]]<=$J$7,INDEX(Generowanie_Zamówienia[],MATCH(Podsumowanie_[[#This Row],[L.p.]],Generowanie_Zamówienia[Zliczanie],0),4),"") | H18: =IFERROR(Podsumowanie_[[#This Row],[Ilość op.]]*Podsumowanie_[[#This Row],[Cena netto za szt.]]*INDEX(Generowanie_Zamówienia[],MATCH(Podsumowanie_[[#This Row],[L.p.]],Generowanie_Zamówienia[Zliczanie],0),3),"")
D19: 12 | E19: =IF(Podsumowanie_[[#This Row],[L.p.]]<=$J$7,INDEX(Generowanie_Zamówienia[],MATCH(Podsumowanie_[[#This Row],[L.p.]],Generowanie_Zamówienia[Zliczanie],0),9),"") | F19: =IF(Podsumowanie_[[#This Row],[L.p.]]<=$J$7,INDEX(Generowanie_Zamówienia[],MATCH(Podsumowanie_[[#This Row],[L.p.]],Generowanie_Zamówienia[Zliczanie],0),2),"") | G19: =IF(Podsumowanie_[[#This Row],[L.p.]]<=$J$7,INDEX(Generowanie_Zamówienia[],MATCH(Podsumowanie_[[#This Row],[L.p.]],Generowanie_Zamówienia[Zliczanie],0),4),"") | H19: =IFERROR(Podsumowanie_[[#This Row],[Ilość op.]]*Podsumowanie_[[#This Row],[Cena netto za szt.]]*INDEX(Generowanie_Zamówienia[],MATCH(Podsumowanie_[[#This Row],[L.p.]],Generowanie_Zamówienia[Zliczanie],0),3),"")
... D686: 679 | E686: =IF(Podsumowanie_[[#This Row],[L.p.]]<=$J$7,INDEX(Generowanie_Zamówienia[],MATCH(Podsumowanie_[[#This Row],[L.p.]],Generowanie_Zamówienia[Zliczanie],0),9),"") | F686: =IF(Podsumowanie_[[#This Row],[L.p.]]<=$J$7,INDEX(Generowanie_Zamówienia[],MATCH(Podsumowanie_[[#This Row],[L.p.]],Generowanie_Zamówienia[Zliczanie],0),2),"") | G686: =IF(Podsumowanie_[[#This Row],[L.p.]]<=$J$7,INDEX(Generowanie_Zamówienia[],MATCH(Podsumowanie_[[#This Row],[L.p.]],Generowanie_Zamówienia[Zliczanie],0),4),"") | H686: =IFERROR(Podsumowanie_[[#This Row],[Ilość op.]]*Podsumowanie_[[#This Row],[Cena netto za szt.]]*INDEX(Generowanie_Zamówienia[],MATCH(Podsumowanie_[[#This Row],[L.p.]],Generowanie_Zamówienia[Zliczanie],0),3),"")

Sheet Generowanie podsumowania zam
A1: KOD_XL | B1: ILOŚĆ OP. ZAMAWIANA | C1: ILOŚC W OP. | D1: CENA | E1: WARTOŚĆ | F1: Pakiet | G1: Nazwa arkusza | H1: Zliczanie | I1: Nazwa | J1: Ilość w sumie | L1: NAZWA PAKIETU | M1: KOD COMARCH | N1: Ilość op. w pak | O1: Ilość szt. w pak | P1: CENA | Q1: Nazwa arkusza | S1: Tutaj wpisz z której kolumny arkusz ma brać cenę we wsadzie ofertowym(numer kolumny licząc od lewej) | U1: 24
A2: =Wsad_Ofertowy[[#This Row],[Kod]] -> ASSA0031 | B2: =IFERROR( INDEX(INDIRECT("'"&Generowanie_Zamówienia[[#This Row],[Nazwa arkusza]]&"'!A1:S1500",TRUE), MATCH(Generowanie_Zamówienia[[#This Row],[KOD_XL]],INDIRECT("'"&Generowanie_Zamówienia[[#This Row],[Nazwa arkusza]]&"'!S1:S1500",TRUE),0), 15),0) -> 0 | C2: =INDEX(Wsad_Ofertowy[],MATCH(Generowanie_Zamówienia[[#This Row],[KOD_XL]],Wsad_Ofertowy[Kod],0),21) -> 12 | D2: {=INDEX(Wsad_Ofertowy[],MATCH(Generowanie_Zamówienia[[#This Row],[KOD_XL]],Wsad_Ofertowy[Kod],0),$U$1)} -> 3.35 | E2: =IFERROR(Generowanie_Zamówienia[[#This Row],[ILOŚĆ OP. ZAMAWIANA]]*Generowanie_Zamówienia[[#This Row],[ILOŚC W OP.]]*Generowanie_Zamówienia[[#This Row],[CENA]],"") -> 0 | F2: =INDEX(Wsad_Ofertowy[],MATCH(Generowanie_Zamówienia[[#This Row],[KOD_XL]],Wsad_Ofertowy[Kod],0),MATCH("nazwa pakietu",Wsad_Ofertowy[#Headers],0)) -> LED_WKŁADY | G2: =IF(MID(Generowanie_Zamówienia[[#This Row],[KOD_XL]],1,3)="PAK", INDEX(Cennik_pakietów[],MATCH(Generowanie_Zamówienia[[#This Row],[KOD_XL]],Cennik_pakietów[KOD COMARCH],0),MATCH("Nazwa arkusza",Cennik_pakietów[#Headers],0)), INDEX(Cennik_pakietów[],MATCH(Generowanie_Zamówienia[[#This Row],[Pakiet]],Cennik_pakietów[NAZWA PAKIETU],0),MATCH("Nazwa arkusza",Cennik_pakietów[#Headers],0))) -> wkłady_led | H2: =IF(Generowanie_Zamówienia[[#This Row],[ILOŚĆ OP. ZAMAWIANA]]>0,COUNTIFS($B$1:B2,">0"),"") | I2: =INDEX(Wsad_Ofertowy[],MATCH(Generowanie_Zamówienia[[#This Row],[KOD_XL]],Wsad_Ofertowy[Kod],0),MATCH("Nazwa",Wsad_Ofertowy[#Headers],0)) -> Ass Świetlik S1 - biały | J2: =Generowanie_Zamówienia[[#This Row],[ILOŚĆ OP. ZAMAWIANA]]*Generowanie_Zamówienia[[#This Row],[ILOŚC W OP.]] -> 0 | L2: DUŻE | M2: 0 | N2: 0 | O2: 0 | P2: 0 | Q2: duże
A3: =Wsad_Ofertowy[[#This Row],[Kod]] -> ASSA0032 | B3: =IFERROR( INDEX(INDIRECT("'"&Generowanie_Zamówienia[[#This Row],[Nazwa arkusza]]&"'!A1:S1500",TRUE), MATCH(Generowanie_Zamówienia[[#This Row],[KOD_XL]],INDIRECT("'"&Generowanie_Zamówienia[[#This Row],[Nazwa arkusza]]&"'!S1:S1500",TRUE),0), 15),0) -> 0 | C3: =INDEX(Wsad_Ofertowy[],MATCH(Generowanie_Zamówienia[[#This Row],[KOD_XL]],Wsad_Ofertowy[Kod],0),21) -> 12 | D3: {=INDEX(Wsad_Ofertowy[],MATCH(Generowanie_Zamówienia[[#This Row],[KOD_XL]],Wsad_Ofertowy[Kod],0),$U$1)} -> 3.35 | E3: =IFERROR(Generowanie_Zamówienia[[#This Row],[ILOŚĆ OP. ZAMAWIANA]]*Generowanie_Zamówienia[[#This Row],[ILOŚC W OP.]]*Generowanie_Zamówienia[[#This Row],[CENA]],"") -> 0 | F3: =INDEX(Wsad_Ofertowy[],MATCH(Generowanie_Zamówienia[[#This Row],[KOD_XL]],Wsad_Ofertowy[Kod],0),MATCH("nazwa pakietu",Wsad_Ofertowy[#Headers],0)) -> LED_WKŁADY | G3: =IF(MID(Generowanie_Zamówienia[[#This Row],[KOD_XL]],1,3)="PAK", INDEX(Cennik_pakietów[],MATCH(Generowanie_Zamówienia[[#This Row],[KOD_XL]],Cennik_pakietów[KOD COMARCH],0),MATCH("Nazwa arkusza",Cennik_pakietów[#Headers],0)), INDEX(Cennik_pakietów[],MATCH(Generowanie_Zamówienia[[#This Row],[Pakiet]],Cennik_pakietów[NAZWA PAKIETU],0),MATCH("Nazwa arkusza",Cennik_pakietów[#Headers],0))) -> wkłady_led | H3: =IF(Generowanie_Zamówienia[[#This Row],[ILOŚĆ OP. ZAMAWIANA]]>0,COUNTIFS($B$1:B3,">0"),"") | I3: =INDEX(Wsad_Ofertowy[],MATCH(Generowanie_Zamówienia[[#This Row],[KOD_XL]],Wsad_Ofertowy[Kod],0),MATCH("Nazwa",Wsad_Ofertowy[#Headers],0)) -> Ass Świetlik S1 - czerwony | J3: =Generowanie_Zamówienia[[#This Row],[ILOŚĆ OP. ZAMAWIANA]]*Generowanie_Zamówienia[[#This Row],[ILOŚC W OP.]] -> 0 | L3: LEDOWE | M3: 0 | N3: 0 | O3: 0 | P3: 0 | Q3: Znicze_led
A4: =Wsad_Ofertowy[[#This Row],[Kod]] -> ASSA0033 | B4: =IFERROR( INDEX(INDIRECT("'"&Generowanie_Zamówienia[[#This Row],[Nazwa arkusza]]&"'!A1:S1500",TRUE), MATCH(Generowanie_Zamówienia[[#This Row],[KOD_XL]],INDIRECT("'"&Generowanie_Zamówienia[[#This Row],[Nazwa arkusza]]&"'!S1:S1500",TRUE),0), 15),0) -> 0 | C4: =INDEX(Wsad_Ofertowy[],MATCH(Generowanie_Zamówienia[[#This Row],[KOD_XL]],Wsad_Ofertowy[Kod],0),21) -> 12 | D4: {=INDEX(Wsad_Ofertowy[],MATCH(Generowanie_Zamówienia[[#This Row],[KOD_XL]],Wsad_Ofertowy[Kod],0),$U$1)} -> 3.35 | E4: =IFERROR(Generowanie_Zamówienia[[#This Row],[ILOŚĆ OP. ZAMAWIANA]]*Generowanie_Zamówienia[[#This Row],[ILOŚC W OP.]]*Generowanie_Zamówienia[[#This Row],[CENA]],"") -> 0 | F4: =INDEX(Wsad_Ofertowy[],MATCH(Generowanie_Zamówienia[[#This Row],[KOD_XL]],Wsad_Ofertowy[Kod],0),MATCH("Nazwa Pakietu",Wsad_Ofertowy[#Headers],0)) -> LED_WKŁADY | G4: =IF(MID(Generowanie_Zamówienia[[#This Row],[KOD_XL]],1,3)="PAK", INDEX(Cennik_pakietów[],MATCH(Generowanie_Zamówienia[[#This Row],[KOD_XL]],Cennik_pakietów[KOD COMARCH],0),MATCH("Nazwa arkusza",Cennik_pakietów[#Headers],0)), INDEX(Cennik_pakietów[],MATCH(Generowanie_Zamówienia[[#This Row],[Pakiet]],Cennik_pakietów[NAZWA PAKIETU],0),MATCH("Nazwa arkusza",Cennik_pakietów[#Headers],0))) -> wkłady_led | H4: =IF(Generowanie_Zamówienia[[#This Row],[ILOŚĆ OP. ZAMAWIANA]]>0,COUNTIFS($B$1:B4,">0"),"") | I4: =INDEX(Wsad_Ofertowy[],MATCH(Generowanie_Zamówienia[[#This Row],[KOD_XL]],Wsad_Ofertowy[Kod],0),MATCH("Nazwa",Wsad_Ofertowy[#Headers],0)) -> Ass Świetlik S1 - fioletowy | J4: =Generowanie_Zamówienia[[#This Row],[ILOŚĆ OP. ZAMAWIANA]]*Generowanie_Zamówienia[[#This Row],[ILOŚC W OP.]] -> 0 | L4: ŚREDNIE | M4: 0 | N4: 0 | O4: 0 | P4: 0 | Q4: średnie
A5: =Wsad_Ofertowy[[#This Row],[Kod]] -> ASSA0034 | B5: =IFERROR( INDEX(INDIRECT("'"&Generowanie_Zamówienia[[#This Row],[Nazwa arkusza]]&"'!A1:S1500",TRUE), MATCH(Generowanie_Zamówienia[[#This Row],[KOD_XL]],INDIRECT("'"&Generowanie_Zamówienia[[#This Row],[Nazwa arkusza]]&"'!S1:S1500",TRUE),0), 15),0) -> 0 | C5: =INDEX(Wsad_Ofertowy[],MATCH(Generowanie_Zamówienia[[#This Row],[KOD_XL]],Wsad_Ofertowy[Kod],0),21) -> 24 | D5: {=INDEX(Wsad_Ofertowy[],MATCH(Generowanie_Zamówienia[[#This Row],[KOD_XL]],Wsad_Ofertowy[Kod],0),$U$1)} -> 3.35 | E5: =IFERROR(Generowanie_Zamówienia[[#This Row],[ILOŚĆ OP. ZAMAWIANA]]*Generowanie_Zamówienia[[#This Row],[ILOŚC W OP.]]*Generowanie_Zamówienia[[#This Row],[CENA]],"") -> 0 | F5: =INDEX(Wsad_Ofertowy[],MATCH(Generowanie_Zamówienia[[#This Row],[KOD_XL]],Wsad_Ofertowy[Kod],0),MATCH("nazwa pakietu",Wsad_Ofertowy[#Headers],0)) -> LED_WKŁADY | G5: =IF(MID(Generowanie_Zamówienia[[#This Row],[KOD_XL]],1,3)="PAK", INDEX(Cennik_pakietów[],MATCH(Generowanie_Zamówienia[[#This Row],[KOD_XL]],Cennik_pakietów[KOD COMARCH],0),MATCH("Nazwa arkusza",Cennik_pakietów[#Headers],0)), INDEX(Cennik_pakietów[],MATCH(Generowanie_Zamówienia[[#This Row],[Pakiet]],Cennik_pakietów[NAZWA PAKIETU],0),MATCH("Nazwa arkusza",Cennik_pakietów[#Headers],0))) -> wkłady_led | H5: =IF(Generowanie_Zamówienia[[#This Row],[ILOŚĆ OP. ZAMAWIANA]]>0,COUNTIFS($B$1:B5,">0"),"") | I5: =INDEX(Wsad_Ofertowy[],MATCH(Generowanie_Zamówienia[[#This Row],[KOD_XL]],Wsad_Ofertowy[Kod],0),MATCH("Nazwa",Wsad_Ofertowy[#Headers],0)) -> Ass Świetlik S1 - mix | J5: =Generowanie_Zamówienia[[#This Row],[ILOŚĆ OP. ZAMAWIANA]]*Generowanie_Zamówienia[[#This Row],[ILOŚC W OP.]] -> 0 | L5: KONIEC_SERII | M5: 0 | N5: 0 | O5: 0 | P5: 0 | Q5: koniec serii
A6: =Wsad_Ofertowy[[#This Row],[Kod]] -> ASSA0035 | B6: =IFERROR( INDEX(INDIRECT("'"&Generowanie_Zamówienia[[#This Row],[Nazwa arkusza]]&"'!A1:S1500",TRUE), MATCH(Generowanie_Zamówienia[[#This Row],[KOD_XL]],INDIRECT("'"&Generowanie_Zamówienia[[#This Row],[Nazwa arkusza]]&"'!S1:S1500",TRUE),0), 15),0) -> 0 | C6: =INDEX(Wsad_Ofertowy[],MATCH(Generowanie_Zamówienia[[#This Row],[KOD_XL]],Wsad_Ofertowy[Kod],0),21) -> 12 | D6: {=INDEX(Wsad_Ofertowy[],MATCH(Generowanie_Zamówienia[[#This Row],[KOD_XL]],Wsad_Ofertowy[Kod],0),$U$1)} -> 3.35 | E6: =IFERROR(Generowanie_Zamówienia[[#This Row],[ILOŚĆ OP. ZAMAWIANA]]*Generowanie_Zamówienia[[#This Row],[ILOŚC W OP.]]*Generowanie_Zamówienia[[#This Row],[CENA]],"") -> 0 | F6: =INDEX(Wsad_Ofertowy[],MATCH(Generowanie_Zamówienia[[#This Row],[KOD_XL]],Wsad_Ofertowy[Kod],0),MATCH("nazwa pakietu",Wsad_Ofertowy[#Headers],0)) -> LED_WKŁADY | G6: =IF(MID(Generowanie_Zamówienia[[#This Row],[KOD_XL]],1,3)="PAK", INDEX(Cennik_pakietów[],MATCH(Generowanie_Zamówienia[[#This Row],[KOD_XL]],Cennik_pakietów[KOD COMARCH],0),MATCH("Nazwa arkusza",Cennik_pakietów[#Headers],0)), INDEX(Cennik_pakietów[],MATCH(Generowanie_Zamówienia[[#This Row],[Pakiet]],Cennik_pakietów[NAZWA PAKIETU],0),MATCH("Nazwa arkusza",Cennik_pakietów[#Headers],0))) -> wkłady_led | H6: =IF(Generowanie_Zamówienia[[#This Row],[ILOŚĆ OP. ZAMAWIANA]]>0,COUNTIFS($B$1:B6,">0"),"") | I6: =INDEX(Wsad_Ofertowy[],MATCH(Generowanie_Zamówienia[[#This Row],[KOD_XL]],Wsad_Ofertowy[Kod],0),MATCH("Nazwa",Wsad_Ofertowy[#Headers],0)) -> Ass Świetlik S1 - niebieski | J6: =Generowanie_Zamówienia[[#This Row],[ILOŚĆ OP. ZAMAWIANA]]*Generowanie_Zamówienia[[#This Row],[ILOŚC W OP.]] -> 0 | L6: LED_WKŁADY | M6: 0 | N6: 0 | O6: 0 | P6: 0 | Q6: wkłady_led
A7: =Wsad_Ofertowy[[#This Row],[Kod]] -> ASSA0036 | B7: =IFERROR( INDEX(INDIRECT("'"&Generowanie_Zamówienia[[#This Row],[Nazwa arkusza]]&"'!A1:S1500",TRUE), MATCH(Generowanie_Zamówienia[[#This Row],[KOD_XL]],INDIRECT("'"&Generowanie_Zamówienia[[#This Row],[Nazwa arkusza]]&"'!S1:S1500",TRUE),0), 15),0) -> 0 | C7: =INDEX(Wsad_Ofertowy[],MATCH(Generowanie_Zamówienia[[#This Row],[KOD_XL]],Wsad_Ofertowy[Kod],0),21) -> 12 | D7: {=INDEX(Wsad_Ofertowy[],MATCH(Generowanie_Zamówienia[[#This Row],[KOD_XL]],Wsad_Ofertowy[Kod],0),$U$1)} -> 3.35 | E7: =IFERROR(Generowanie_Zamówienia[[#This Row],[ILOŚĆ OP. ZAMAWIANA]]*Generowanie_Zamówienia[[#This Row],[ILOŚC W OP.]]*Generowanie_Zamówienia[[#This Row],[CENA]],"") -> 0 | F7: =INDEX(Wsad_Ofertowy[],MATCH(Generowanie_Zamówienia[[#This Row],[KOD_XL]],Wsad_Ofertowy[Kod],0),MATCH("nazwa pakietu",Wsad_Ofertowy[#Headers],0)) -> LED_WKŁADY | G7: =IF(MID(Generowanie_Zamówienia[[#This Row],[KOD_XL]],1,3)="PAK", INDEX(Cennik_pakietów[],MATCH(Generowanie_Zamówienia[[#This Row],[KOD_XL]],Cennik_pakietów[KOD COMARCH],0),MATCH("Nazwa arkusza",Cennik_pakietów[#Headers],0)), INDEX(Cennik_pakietów[],MATCH(Generowanie_Zamówienia[[#This Row],[Pakiet]],Cennik_pakietów[NAZWA PAKIETU],0),MATCH("Nazwa arkusza",Cennik_pakietów[#Headers],0))) -> wkłady_led | H7: =IF(Generowanie_Zamówienia[[#This Row],[ILOŚĆ OP. ZAMAWIANA]]>0,COUNTIFS($B$1:B7,">0"),"") | I7: =INDEX(Wsad_Ofertowy[],MATCH(Generowanie_Zamówienia[[#This Row],[KOD_XL]],Wsad_Ofertowy[Kod],0),MATCH("Nazwa",Wsad_Ofertowy[#Headers],0)) -> Ass Świetlik S1 - pomarańcz | J7: =Generowanie_Zamówienia[[#This Row],[ILOŚĆ OP. ZAMAWIANA]]*Generowanie_Zamówienia[[#This Row],[ILOŚC W OP.]] -> 0 | L7: ZALEWANE | M7: 0 | N7: 0 | O7: 0 | P7: 0 | Q7: zalewane
A8: =Wsad_Ofertowy[[#This Row],[Kod]] -> ASSA0037 | B8: =IFERROR( INDEX(INDIRECT("'"&Generowanie_Zamówienia[[#This Row],[Nazwa arkusza]]&"'!A1:S1500",TRUE), MATCH(Generowanie_Zamówienia[[#This Row],[KOD_XL]],INDIRECT("'"&Generowanie_Zamówienia[[#This Row],[Nazwa arkusza]]&"'!S1:S1500",TRUE),0), 15),0) -> 0 | C8: =INDEX(Wsad_Ofertowy[],MATCH(Generowanie_Zamówienia[[#This Row],[KOD_XL]],Wsad_Ofertowy[Kod],0),21) -> 12 | D8: {=INDEX(Wsad_Ofertowy[],MATCH(Generowanie_Zamówienia[[#This Row],[KOD_XL]],Wsad_Ofertowy[Kod],0),$U$1)} -> 3.35 | E8: =IFERROR(Generowanie_Zamówienia[[#This Row],[ILOŚĆ OP. ZAMAWIANA]]*Generowanie_Zamówienia[[#This Row],[ILOŚC W OP.]]*Generowanie_Zamówienia[[#This Row],[CENA]],"") -> 0 | F8: =INDEX(Wsad_Ofertowy[],MATCH(Generowanie_Zamówienia[[#This Row],[KOD_XL]],Wsad_Ofertowy[Kod],0),MATCH("nazwa pakietu",Wsad_Ofertowy[#Headers],0)) -> LED_WKŁADY | G8: =IF(MID(Generowanie_Zamówienia[[#This Row],[KOD_XL]],1,3)="PAK", INDEX(Cennik_pakietów[],MATCH(Generowanie_Zamówienia[[#This Row],[KOD_XL]],Cennik_pakietów[KOD COMARCH],0),MATCH("Nazwa arkusza",Cennik_pakietów[#Headers],0)), INDEX(Cennik_pakietów[],MATCH(Generowanie_Zamówienia[[#This Row],[Pakiet]],Cennik_pakietów[NAZWA PAKIETU],0),MATCH("Nazwa arkusza",Cennik_pakietów[#Headers],0))) -> wkłady_led | H8: =IF(Generowanie_Zamówienia[[#This Row],[ILOŚĆ OP. ZAMAWIANA]]>0,COUNTIFS($B$1:B8,">0"),"") | I8: =INDEX(Wsad_Ofertowy[],MATCH(Generowanie_Zamówienia[[#This Row],[KOD_XL]],Wsad_Ofertowy[Kod],0),MATCH("Nazwa",Wsad_Ofertowy[#Headers],0)) -> Ass Świetlik S1 - zielony | J8: =Generowanie_Zamówienia[[#This Row],[ILOŚĆ OP. ZAMAWIANA]]*Generowanie_Zamówienia[[#This Row],[ILOŚC W OP.]] -> 0 | L8: LAMPIONY | M8: 0 | N8: 0 | O8: 0 | P8: 0 | Q8: lampiony
A9: =Wsad_Ofertowy[[#This Row],[Kod]] -> ASSA0038 | B9: =IFERROR( INDEX(INDIRECT("'"&Generowanie_Zamówienia[[#This Row],[Nazwa arkusza]]&"'!A1:S1500",TRUE), MATCH(Generowanie_Zamówienia[[#This Row],[KOD_XL]],INDIRECT("'"&Generowanie_Zamówienia[[#This Row],[Nazwa arkusza]]&"'!S1:S1500",TRUE),0), 15),0) -> 0 | C9: =INDEX(Wsad_Ofertowy[],MATCH(Generowanie_Zamówienia[[#This Row],[KOD_XL]],Wsad_Ofertowy[Kod],0),21) -> 12 | D9: {=INDEX(Wsad_Ofertowy[],MATCH(Generowanie_Zamówienia[[#This Row],[KOD_XL]],Wsad_Ofertowy[Kod],0),$U$1)} -> 3.35 | E9: =IFERROR(Generowanie_Zamówienia[[#This Row],[ILOŚĆ OP. ZAMAWIANA]]*Generowanie_Zamówienia[[#This Row],[ILOŚC W OP.]]*Generowanie_Zamówienia[[#This Row],[CENA]],"") -> 0 | F9: =INDEX(Wsad_Ofertowy[],MATCH(Generowanie_Zamówienia[[#This Row],[KOD_XL]],Wsad_Ofertowy[Kod],0),MATCH("nazwa pakietu",Wsad_Ofertowy[#Headers],0)) -> LED_WKŁADY | G9: =IF(MID(Generowanie_Zamówienia[[#This Row],[KOD_XL]],1,3)="PAK", INDEX(Cennik_pakietów[],MATCH(Generowanie_Zamówienia[[#This Row],[KOD_XL]],Cennik_pakietów[KOD COMARCH],0),MATCH("Nazwa arkusza",Cennik_pakietów[#Headers],0)), INDEX(Cennik_pakietów[],MATCH(Generowanie_Zamówienia[[#This Row],[Pakiet]],Cennik_pakietów[NAZWA PAKIETU],0),MATCH("Nazwa arkusza",Cennik_pakietów[#Headers],0))) -> wkłady_led | H9: =IF(Generowanie_Zamówienia[[#This Row],[ILOŚĆ OP. ZAMAWIANA]]>0,COUNTIFS($B$1:B9,">0"),"") | I9: =INDEX(Wsad_Ofertowy[],MATCH(Generowanie_Zamówienia[[#This Row],[KOD_XL]],Wsad_Ofertowy[Kod],0),MATCH("Nazwa",Wsad_Ofertowy[#Headers],0)) -> Ass Świetlik S1 - zmieniający | J9: =Generowanie_Zamówienia[[#This Row],[ILOŚĆ OP. ZAMAWIANA]]*Generowanie_Zamówienia[[#This Row],[ILOŚC W OP.]] -> 0 | L9: ZAPALARKI | M9: 0 | N9: 0 | O9: 0 | P9: 0 | Q9: Zapalarki
A10: =Wsad_Ofertowy[[#This Row],[Kod]] -> ASSA0039 | B10: =IFERROR( INDEX(INDIRECT("'"&Generowanie_Zamówienia[[#This Row],[Nazwa arkusza]]&"'!A1:S1500",TRUE), MATCH(Generowanie_Zamówienia[[#This Row],[KOD_XL]],INDIRECT("'"&Generowanie_Zamówienia[[#This Row],[Nazwa arkusza]]&"'!S1:S1500",TRUE),0), 15),0) -> 0 | C10: =INDEX(Wsad_Ofertowy[],MATCH(Generowanie_Zamówienia[[#This Row],[KOD_XL]],Wsad_Ofertowy[Kod],0),21) -> 12 | D10: {=INDEX(Wsad_Ofertowy[],MATCH(Generowanie_Zamówienia[[#This Row],[KOD_XL]],Wsad_Ofertowy[Kod],0),$U$1)} -> 3.35 | E10: =IFERROR(Generowanie_Zamówienia[[#This Row],[ILOŚĆ OP. ZAMAWIANA]]*Generowanie_Zamówienia[[#This Row],[ILOŚC W OP.]]*Generowanie_Zamówienia[[#This Row],[CENA]],"") -> 0 | F10: =INDEX(Wsad_Ofertowy[],MATCH(Generowanie_Zamówienia[[#This Row],[KOD_XL]],Wsad_Ofertowy[Kod],0),MATCH("nazwa pakietu",Wsad_Ofertowy[#Headers],0)) -> LED_WKŁADY | G10: =IF(MID(Generowanie_Zamówienia[[#This Row],[KOD_XL]],1,3)="PAK", INDEX(Cennik_pakietów[],MATCH(Generowanie_Zamówienia[[#This Row],[KOD_XL]],Cennik_pakietów[KOD COMARCH],0),MATCH("Nazwa arkusza",Cennik_pakietów[#Headers],0)), INDEX(Cennik_pakietów[],MATCH(Generowanie_Zamówienia[[#This Row],[Pakiet]],Cennik_pakietów[NAZWA PAKIETU],0),MATCH("Nazwa arkusza",Cennik_pakietów[#Headers],0))) -> wkłady_led | H10: =IF(Generowanie_Zamówienia[[#This Row],[ILOŚĆ OP. ZAMAWIANA]]>0,COUNTIFS($B$1:B10,">0"),"") | I10: =INDEX(Wsad_Ofertowy[],MATCH(Generowanie_Zamówienia[[#This Row],[KOD_XL]],Wsad_Ofertowy[Kod],0),MATCH("Nazwa",Wsad_Ofertowy[#Headers],0)) -> Ass Świetlik S1 - żółty | J10: =Generowanie_Zamówienia[[#This Row],[ILOŚĆ OP. ZAMAWIANA]]*Generowanie_Zamówienia[[#This Row],[ILOŚC W OP.]] -> 0 | L10: MAŁE | M10: 0 | N10: 0 | O10: 0 | P10: 0 | Q10: małe
